Workbook

Sheet Clubs
A1: Level | B1: Name | C1: Date Established | D1: Governorate | E1: Category | F1: Score | G1: Official District
A2: 1 | B2: Pyramids FC | C2: 2008 | D2: Cairo | E2: Men | F2: 5 | G2: Tagamoa
A3: 1 | B3: Zamalek | C3: 1911 | D3: Cairo | E3: Men | F3: 5 | G3: Agouza
A4: 1 | B4: Al Ahly | C4: 1907 | D4: Cairo | E4: Men | F4: 5 | G4: Zamalek
A5: 1 | B5: Tala'e El Gaish | C5: 1995 | D5: Cairo | E5: Men | F5: 5 | G5: Masr El Gedida
A6: 1 | B6: Al Masry | C6: 1920 | D6: Port Said | E6: Men | F6: 5
A7: 1 | B7: Al Ittihad | C7: 1914 | D7: Alexandria | E7: Men | F7: 5
A8: 1 | B8: El Gouna | C8: 2003 | D8: Red Sea | E8: Men | F8: 5
A9: 1 | B9: Zed FC | C9: 2009 | D9: Giza | E9: Men | F9: 5 | G9: Zayed
A10: 1 | B10: Ceramica Cleopatra | C10: 2007 | D10: Giza | E10: Men | F10: 5 | G10: 6th of October
A11: 1 | B11: Modern Sport | C11: 2011 | D11: Cairo | E11: Men | F11: 5 | G11: Nasr City
A12: 1 | B12: Bank Al Ahly SC | C12: 1951 | D12: Cairo | E12: Men | F12: 5 | G12: Agouza
A13: 1 | B13: Enppi SC | C13: 1985 | D13: Cairo | E13: Men | F13: 5 | G13: Tagamoa
A14: 1 | B14: Pharco FC | C14: 2010 | D14: Alexandria | E14: Men | F14: 5
A15: 1 | B15: Ismaily SC | C15: 1924 | D15: Ismailia | E15: Men | F15: 5
A16: 1 | B16: Smouha SC | C16: 1945 | D16: Alexandria | E16: Men | F16: 5
A17: 1 | B17: Petrojet | C17: 2000 | D17: Suez | E17: Men | F17: 5
A18: 1 | B18: Ghazl El Mahalla | C18: 1936 | D18: Gharbia | E18: Men | F18: 5
A19: 1 | B19: Haras Al Hodoud SC | C19: 1932 | D19: Alexandria | E19: Men | F19: 5
A20: 1 | B20: Wadi Degla SC | C20: 2002 | D20: Cairo | E20: Men | F20: 5 | G20: Maadi
A21: 1 | B21: Kahraba' Ismailia | C21: 1935 | D21: Ismailia | E21: Men | F21: 5
A22: 1 | B22: Al Mokawloon Al Arab | C22: 1973 | D22: Cairo | E22: Men | F22: 5 | G22: Nasr City
A23: 2 | B23: La Viena | C23: 2020 | D23: Beni Suef | E23: Men | F23: 3
A24: 2 | B24: Sekka El Hadid | C24: 1903 | D24: Cairo | E24: Men | F24: 3 | G24: Nasr City
A25: 2 | B25: Tanta | C25: 1932 | D25: Gharbia | E25: Men | F25: 3
A26: 2 | B26: Al Qanah | C26: 1964 | D26: Ismailia | E26: Men | F26: 3
A27: 2 | B27: Raya | C27: 2000 | D27: Beheira | E27: Men | F27: 3
A28: 2 | B28: Abo Qir Cement | C28: 1976 | D28: Alexandria | E28: Men | F28: 3
A29: 2 | B29: Proxy | C29: 2019 | D29: Beheira | E29: Men | F29: 3
A30: 2 | B30: Assuit Petroleum SC | C30: 1990 | D30: Assiut | E30: Men | F30: 3
A31: 2 | B31: WE Telecom | C31: 2006 | D31: Cairo | E31: Men | F31: 3 | G31: Nasr City
A32: 2 | B32: Aswan | C32: 1930 | D32: Aswan | E32: Men | F32: 3
A33: 2 | B33: Tersana SC | C33: 1921 | D33: Giza | E33: Men | F33: 3 | G33: Agouza
A34: 2 | B34: Daryot SC | C34: 1972 | D34: Assiut | E34: Men | F34: 3
A35: 2 | B35: Mansoura SC | C35: 1932 | D35: Dakahlia | E35: Men | F35: 3
A36: 2 | B36: Dakhleya SC | C36: 2005 | D36: Cairo | E36: Men | F36: 3 | G36: Nasr City
A37: 2 | B37: Baladiyat El Mahalla | C37: 1931 | D37: Gharbia | E37: Men | F37: 3
A38: 2 | B38: FC Masar | C38: 2019 | D38: Cairo | E38: Men | F38: 3 | G38: 6th of October
A39: 2 | B39: Maleyat Kafr El Zayat SC | C39: 1948 | D39: Gharbia | E39: Men | F39: 3
A40: 2 | B40: El Entag El Harby SC | C40: 2004 | D40: Cairo | E40: Men | F40: 3 | G40: El Salam
...

Sheet Governorates
A1: Governorate | B1: Population | C1: Area (km2) | D1: Density (km2) | E1: GDP (PPP) | F1: GDP per capita | G1: Density_Z | H1: GDP_Z | I1: GDP per capita_Z | J1: Economic P | K1: Sporting Rep | L1: Premier League | M1: Div2 | N1: Div 3 | O1: Womens | P1: Futsal | Q1: Score | R1: Rep_Z | S1: Premier League-Z | T1: Div_Z | U1: Div3_Z | V1: Womens_Z | W1: Futsal_Z | X1: Football Index | Y1: Overperformance Index
A2: Cairo | B2: 10492097 | C2: 2837 | D2: =SUM(B2/C2) -> 3698.307 | E2: 413541 | F2: 41169 | G2: =(D2-AVERAGE(D$2:D$28))/_xlfn.STDEV.P(D$2:D$28) -> 2.2107871 | H2: =(E2-AVERAGE(E$2:E$28))/_xlfn.STDEV.P(E$2:E$28) -> 4.5481115 | I2: =(F2-AVERAGE(F$2:F$28))/_xlfn.STDEV.P(F$2:F$28) -> 0.88488902 | J2: =SUM((I2*0.3)+(H2*0.4)+(G2*0.3)) -> 2.7479474 | K2: =COUNTIFS(Clubs!D:D,"*Cairo*") -> 33 | L2: =COUNTIFS(Clubs!$D$2:D22,"*Cairo*") -> 9 | M2: =COUNTIFS(Clubs!$D$23:$D$40,"*Cairo*") -> 5 | N2: =COUNTIFS(Clubs!$D$41:$D$104,"*Cairo*") -> 5 | O2: =COUNTIFS(Clubs!$D$105:$D$121,"*Cairo*") -> 11 | P2: =COUNTIFS(Clubs!$D$122:$D$132,"*Cairo*") -> 3 | Q2: =SUMIF(Clubs!D:D,"*Cairo*",Clubs!F:F) -> 104 | R2: =(K2-AVERAGE(K$2:K$28))/_xlfn.STDEV.P(K$2:K$28) -> 4.4151734 | S2: =(L2-AVERAGE(L$2:L$28))/_xlfn.STDEV.P(L$2:L$28) -> 4.4382251 | T2: =(M2-AVERAGE(M$2:M$28))/_xlfn.STDEV.P(M$2:M$28) -> 3.7527767 | U2: =(N2-AVERAGE(N$2:N$28))/_xlfn.STDEV.P(N$2:N$28) -> 1.5852322 | V2: =(O2-AVERAGE(O$2:O$28))/_xlfn.STDEV.P(O$2:O$28) -> 4.872698 | W2: =(P2-AVERAGE(P$2:P$28))/_xlfn.STDEV.P(P$2:P$28) -> 2.6160228 | X2: =SUM(R2*0.3)+(S2*0.3)+(T2*0.15)*(U2*0.07)*(V2*0.15)*(W2*0.03) -> 2.6596026 | Y2: =SUM(X2-J2) -> -0.088344791
A3: Alexandria | B3: 5666831 | C3: 2384 | D3: =SUM(B3/C3) -> 2377.0264 | E3: 124697 | F3: 22914 | G3: =(D3-AVERAGE(D$2:D$28))/_xlfn.STDEV.P(D$2:D$28) -> 1.1285481 | H3: =(E3-AVERAGE(E$2:E$28))/_xlfn.STDEV.P(E$2:E$28) -> 0.90079179 | I3: =(F3-AVERAGE(F$2:F$28))/_xlfn.STDEV.P(F$2:F$28) -> 0.097234862 | J3: =SUM((I3*0.3)+(H3*0.4)+(G3*0.3)) -> 0.72805161 | K3: =COUNTIFS(Clubs!D:D,"*Alexandria*") -> 11 | L3: =COUNTIFS(Clubs!$D$2:$D$22,"*Alexandria*") -> 4 | M3: =COUNTIFS(Clubs!$D$23:$D$40,"*Alexandria*") -> 1 | N3: =COUNTIFS(Clubs!$D$41:$D$104,"*Alexandria*") -> 6 | O3: =COUNTIFS(Clubs!$D$105:$D$121,"*Alexandria*") -> 0 | P3: =COUNTIFS(Clubs!$D$122:$D$132,"*Alexandria*") -> 0 | Q3: =SUMIF(Clubs!D:D,"*Alexandria*",Clubs!F:F) -> 29 | R3: =(K3-AVERAGE(K$2:K$28))/_xlfn.STDEV.P(K$2:K$28) -> 0.96436683 | S3: =(L3-AVERAGE(L$2:L$28))/_xlfn.STDEV.P(L$2:L$28) -> 1.7393044 | T3: =(M3-AVERAGE(M$2:M$28))/_xlfn.STDEV.P(M$2:M$28) -> 0.28867513 | U3: =(N3-AVERAGE(N$2:N$28))/_xlfn.STDEV.P(N$2:N$28) -> 2.188067 | V3: =(O3-AVERAGE(O$2:O$28))/_xlfn.STDEV.P(O$2:O$28) -> -0.29584238 | W3: =(P3-AVERAGE(P$2:P$28))/_xlfn.STDEV.P(P$2:P$28) -> -0.4110893 | X3: =SUM(R3*0.3)+(S3*0.3)+(T3*0.15)*(U3*0.07)*(V3*0.15)*(W3*0.03) -> 0.811105 | Y3: =SUM(X3-J3) -> 0.083053397
A4: Suez | B4: 814520 | C4: 9054 | D4: =SUM(B4/C4) -> 89.962448 | E4: 26251 | F4: 33923 | G4: =(D4-AVERAGE(D$2:D$28))/_xlfn.STDEV.P(D$2:D$28) -> -0.74474808 | H4: =(E4-AVERAGE(E$2:E$28))/_xlfn.STDEV.P(E$2:E$28) -> -0.34231533 | I4: =(F4-AVERAGE(F$2:F$28))/_xlfn.STDEV.P(F$2:F$28) -> 0.57224361 | J4: =SUM((I4*0.3)+(H4*0.4)+(G4*0.3)) -> -0.18867747 | K4: =COUNTIFS(Clubs!D:D,"*Suez*") -> 2 | L4: =COUNTIFS(Clubs!$D$2:$D$22,"*Suez*") -> 1 | M4: =COUNTIFS(Clubs!$D$23:$D$40,"*Suez*") -> 0 | N4: =COUNTIFS(Clubs!$D$41:$D$104,"*Suez*") -> 1 | O4: =COUNTIFS(Clubs!$D$105:$D$121,"*Suez*") -> 0 | P4: =COUNTIFS(Clubs!$D$122:$D$132,"*Suez*") -> 0 | Q4: =SUMIF(Clubs!D:D,"*Suez*",Clubs!F:F) -> 6 | R4: =(K4-AVERAGE(K$2:K$28))/_xlfn.STDEV.P(K$2:K$28) -> -0.44732678 | S4: =(L4-AVERAGE(L$2:L$28))/_xlfn.STDEV.P(L$2:L$28) -> 0.11995203 | T4: =(M4-AVERAGE(M$2:M$28))/_xlfn.STDEV.P(M$2:M$28) -> -0.57735027 | U4: =(N4-AVERAGE(N$2:N$28))/_xlfn.STDEV.P(N$2:N$28) -> -0.82610692 | V4: =(O4-AVERAGE(O$2:O$28))/_xlfn.STDEV.P(O$2:O$28) -> -0.29584238 | W4: =(P4-AVERAGE(P$2:P$28))/_xlfn.STDEV.P(P$2:P$28) -> -0.4110893 | X4: =SUM(R4*0.3)+(S4*0.3)+(T4*0.15)*(U4*0.07)*(V4*0.15)*(W4*0.03) -> -0.098209685 | Y4: =SUM(X4-J4) -> 0.090467789
A5: Port Said | B5: 804500 | C5: 1373 | D5: =SUM(B5/C5) -> 585.94319 | E5: 41903 | F5: 53686 | G5: =(D5-AVERAGE(D$2:D$28))/_xlfn.STDEV.P(D$2:D$28) -> -0.33849848 | H5: =(E5-AVERAGE(E$2:E$28))/_xlfn.STDEV.P(E$2:E$28) -> -0.14467284 | I5: =(F5-AVERAGE(F$2:F$28))/_xlfn.STDEV.P(F$2:F$28) -> 1.4249639 | J5: =SUM((I5*0.3)+(H5*0.4)+(G5*0.3)) -> 0.2680705 | K5: =COUNTIFS(Clubs!D:D,"*Port Said*") -> 4 | L5: =COUNTIFS(Clubs!$D$2:$D$22,"*Port Said*") -> 1 | M5: =COUNTIFS(Clubs!$D$23:$D$40,"*Port Said*") -> 0 | N5: =COUNTIFS(Clubs!$D$41:$D$104,"*Port Said*") -> 2 | O5: =COUNTIFS(Clubs!$D$105:$D$121,"*Port Said*") -> 1 | P5: =COUNTIFS(Clubs!$D$122:$D$132,"*Port Said*") -> 0 | Q5: =SUMIF(Clubs!D:D,"*Port Said*",Clubs!F:F) -> 10 | R5: =(K5-AVERAGE(K$2:K$28))/_xlfn.STDEV.P(K$2:K$28) -> -0.13361709 | S5: =(L5-AVERAGE(L$2:L$28))/_xlfn.STDEV.P(L$2:L$28) -> 0.11995203 | T5: =(M5-AVERAGE(M$2:M$28))/_xlfn.STDEV.P(M$2:M$28) -> -0.57735027 | U5: =(N5-AVERAGE(N$2:N$28))/_xlfn.STDEV.P(N$2:N$28) -> -0.22327214 | V5: =(O5-AVERAGE(O$2:O$28))/_xlfn.STDEV.P(O$2:O$28) -> 0.17402493 | W5: =(P5-AVERAGE(P$2:P$28))/_xlfn.STDEV.P(P$2:P$28) -> -0.4110893 | X5: =SUM(R5*0.3)+(S5*0.3)+(T5*0.15)*(U5*0.07)*(V5*0.15)*(W5*0.03) -> -0.0040999542 | Y5: =SUM(X5-J5) -> -0.27217045
A6: Beheira | B6: 7144387 | C6: 10643 | D6: =SUM(B6/C6) -> 671.27567 | E6: 63653 | F6: 9533 | G6: =(D6-AVERAGE(D$2:D$28))/_xlfn.STDEV.P(D$2:D$28) -> -0.26860405 | H6: =(E6-AVERAGE(E$2:E$28))/_xlfn.STDEV.P(E$2:E$28) -> 0.12997092 | I6: =(F6-AVERAGE(F$2:F$28))/_xlfn.STDEV.P(F$2:F$28) -> -0.48011931 | J6: =SUM((I6*0.3)+(H6*0.4)+(G6*0.3)) -> -0.17262864 | K6: =COUNTIFS(Clubs!D:D,"*Beheira*") -> 4 | L6: =COUNTIFS(Clubs!$D$2:$D$22,"*Beheira*") -> 0 | M6: =COUNTIFS(Clubs!$D$23:$D$40,"*Beheira*") -> 2 | N6: =COUNTIFS(Clubs!$D$41:$D$104,"*Beheira*") -> 2 | O6: =COUNTIFS(Clubs!$D$105:$D$121,"*Beheira*") -> 0 | P6: =COUNTIFS(Clubs!$D$122:$D$132,"*Beheira*") -> 0 | Q6: =SUMIF(Clubs!D:D,"*Beheira*",Clubs!F:F) -> 8 | R6: =(K6-AVERAGE(K$2:K$28))/_xlfn.STDEV.P(K$2:K$28) -> -0.13361709 | S6: =(L6-AVERAGE(L$2:L$28))/_xlfn.STDEV.P(L$2:L$28) -> -0.4198321 | T6: =(M6-AVERAGE(M$2:M$28))/_xlfn.STDEV.P(M$2:M$28) -> 1.1547005 | U6: =(N6-AVERAGE(N$2:N$28))/_xlfn.STDEV.P(N$2:N$28) -> -0.22327214 | V6: =(O6-AVERAGE(O$2:O$28))/_xlfn.STDEV.P(O$2:O$28) -> -0.29584238 | W6: =(P6-AVERAGE(P$2:P$28))/_xlfn.STDEV.P(P$2:P$28) -> -0.4110893 | X6: =SUM(R6*0.3)+(S6*0.3)+(T6*0.15)*(U6*0.07)*(V6*0.15)*(W6*0.03) -> -0.16603624 | Y6: =SUM(X6-J6) -> 0.0065924002
A7: Dakahlia | B7: 7244592 | C7: 3908 | D7: =SUM(B7/C7) -> 1853.7851 | E7: 64790 | F7: 9403 | G7: =(D7-AVERAGE(D$2:D$28))/_xlfn.STDEV.P(D$2:D$28) -> 0.69996977 | H7: =(E7-AVERAGE(E$2:E$28))/_xlfn.STDEV.P(E$2:E$28) -> 0.14432816 | I7: =(F7-AVERAGE(F$2:F$28))/_xlfn.STDEV.P(F$2:F$28) -> -0.48572846 | J7: =SUM((I7*0.3)+(H7*0.4)+(G7*0.3)) -> 0.12200366 | K7: =COUNTIFS(Clubs!D:D,"*Dakahlia*") -> 6 | L7: =COUNTIFS(Clubs!$D$2:$D$22,"*Dakahlia*") -> 0 | M7: =COUNTIFS(Clubs!$D$23:$D$40,"*Dakahlia*") -> 1 | N7: =COUNTIFS(Clubs!$D$41:$D$104,"*Dakahlia*") -> 5 | O7: =COUNTIFS(Clubs!$D$105:$D$121,"*Dakahlia*") -> 0 | P7: =COUNTIFS(Clubs!$D$122:$D$132,"*Dakahlia*") -> 0 | Q7: =SUMIF(Clubs!D:D,"*Dakahlia*",Clubs!F:F) -> 8 | R7: =(K7-AVERAGE(K$2:K$28))/_xlfn.STDEV.P(K$2:K$28) -> 0.1800926 | S7: =(L7-AVERAGE(L$2:L$28))/_xlfn.STDEV.P(L$2:L$28) -> -0.4198321 | T7: =(M7-AVERAGE(M$2:M$28))/_xlfn.STDEV.P(M$2:M$28) -> 0.28867513 | U7: =(N7-AVERAGE(N$2:N$28))/_xlfn.STDEV.P(N$2:N$28) -> 1.5852322 | V7: =(O7-AVERAGE(O$2:O$28))/_xlfn.STDEV.P(O$2:O$28) -> -0.29584238 | W7: =(P7-AVERAGE(P$2:P$28))/_xlfn.STDEV.P(P$2:P$28) -> -0.4110893 | X7: =SUM(R7*0.3)+(S7*0.3)+(T7*0.15)*(U7*0.07)*(V7*0.15)*(W7*0.03) -> -0.071919221 | Y7: =SUM(X7-J7) -> -0.19392288
A8: Damietta | B8: 1657242 | C8: 964 | D8: =SUM(B8/C8) -> 1719.1307 | E8: 24314 | F8: 15338 | G8: =(D8-AVERAGE(D$2:D$28))/_xlfn.STDEV.P(D$2:D$28) -> 0.58967663 | H8: =(E8-AVERAGE(E$2:E$28))/_xlfn.STDEV.P(E$2:E$28) -> -0.36677441 | I8: =(F8-AVERAGE(F$2:F$28))/_xlfn.STDEV.P(F$2:F$28) -> -0.22964917 | J8: =SUM((I8*0.3)+(H8*0.4)+(G8*0.3)) -> -0.038701526 | K8: =COUNTIFS(Clubs!D:D,"*Damietta*") -> 2 | L8: =COUNTIFS(Clubs!$D$2:$D$22,"*Damietta*") -> 0 | M8: =COUNTIFS(Clubs!$D$23:$D$40,"*Damietta*") -> 0 | N8: =COUNTIFS(Clubs!$D$41:$D$104,"*Damietta*") -> 2 | O8: =COUNTIFS(Clubs!$D$105:$D$121,"*Damietta*") -> 0 | P8: =COUNTIFS(Clubs!$D$122:$D$132,"*Damietta*") -> 0 | Q8: =SUMIF(Clubs!D:D,"*Damietta*",Clubs!F:F) -> 2 | R8: =(K8-AVERAGE(K$2:K$28))/_xlfn.STDEV.P(K$2:K$28) -> -0.44732678 | S8: =(L8-AVERAGE(L$2:L$28))/_xlfn.STDEV.P(L$2:L$28) -> -0.4198321 | T8: =(M8-AVERAGE(M$2:M$28))/_xlfn.STDEV.P(M$2:M$28) -> -0.57735027 | U8: =(N8-AVERAGE(N$2:N$28))/_xlfn.STDEV.P(N$2:N$28) -> -0.22327214 | V8: =(O8-AVERAGE(O$2:O$28))/_xlfn.STDEV.P(O$2:O$28) -> -0.29584238 | W8: =(P8-AVERAGE(P$2:P$28))/_xlfn.STDEV.P(P$2:P$28) -> -0.4110893 | X8: =SUM(R8*0.3)+(S8*0.3)+(T8*0.15)*(U8*0.07)*(V8*0.15)*(W8*0.03) -> -0.26014692 | Y8: =SUM(X8-J8) -> -0.2214454
A9: Gharbia | B9: 5587434 | C9: 1946 | D9: =SUM(B9/C9) -> 2871.2405 | E9: 38290 | F9: 7212 | G9: =(D9-AVERAGE(D$2:D$28))/_xlfn.STDEV.P(D$2:D$28) -> 1.5333507 | H9: =(E9-AVERAGE(E$2:E$28))/_xlfn.STDEV.P(E$2:E$28) -> -0.19029527 | I9: =(F9-AVERAGE(F$2:F$28))/_xlfn.STDEV.P(F$2:F$28) -> -0.58026421 | J9: =SUM((I9*0.3)+(H9*0.4)+(G9*0.3)) -> 0.20980782 | K9: =COUNTIFS(Clubs!D:D,"*Dakahlia*") -> 6 | L9: =COUNTIFS(Clubs!$D$2:$D$22,"*Gharbia*") -> 1 | M9: =COUNTIFS(Clubs!$D$23:$D$40,"*Gharbia*") -> 3 | N9: =COUNTIFS(Clubs!$D$41:$D$104,"*Gharbia*") -> 1 | O9: =COUNTIFS(Clubs!$D$105:$D$121,"*Gharbia*") -> 1 | P9: =COUNTIFS(Clubs!$D$122:$D$132,"*Gharbia*") -> 0 | Q9: =SUMIF(Clubs!D:D,"*Gharbia*",Clubs!F:F) -> 18 | R9: =(K9-AVERAGE(K$2:K$28))/_xlfn.STDEV.P(K$2:K$28) -> 0.1800926 | S9: =(L9-AVERAGE(L$2:L$28))/_xlfn.STDEV.P(L$2:L$28) -> 0.11995203 | T9: =(M9-AVERAGE(M$2:M$28))/_xlfn.STDEV.P(M$2:M$28) -> 2.0207259 | U9: =(N9-AVERAGE(N$2:N$28))/_xlfn.STDEV.P(N$2:N$28) -> -0.82610692 | V9: =(O9-AVERAGE(O$2:O$28))/_xlfn.STDEV.P(O$2:O$28) -> 0.17402493 | W9: =(P9-AVERAGE(P$2:P$28))/_xlfn.STDEV.P(P$2:P$28) -> -0.4110893 | X9: =SUM(R9*0.3)+(S9*0.3)+(T9*0.15)*(U9*0.07)*(V9*0.15)*(W9*0.03) -> 0.090019031 | Y9: =SUM(X9-J9) -> -0.11978879
A10: Kafr El Sheikh | B10: 3830112 | C10: 3681 | D10: =SUM(B10/C10) -> 1040.5086 | E10: 33286 | F10: 9193 | G10: =(D10-AVERAGE(D$2:D$28))/_xlfn.STDEV.P(D$2:D$28) -> 0.033828478 | H10: =(E10-AVERAGE(E$2:E$28))/_xlfn.STDEV.P(E$2:E$28) -> -0.25348228 | I10: =(F10-AVERAGE(F$2:F$28))/_xlfn.STDEV.P(F$2:F$28) -> -0.49478939 | J10: =SUM((I10*0.3)+(H10*0.4)+(G10*0.3)) -> -0.23968119 | K10: =COUNTIFS(Clubs!D:D,"*Kafr El Sheikh*") -> 2 | L10: =COUNTIFS(Clubs!$D$2:$D$22,"*Kafr El Sheikh*") -> 0 | M10: =COUNTIFS(Clubs!$D$23:$D$40,"*Kafr El Sheikh*") -> 0 | N10: =COUNTIFS(Clubs!$D$41:$D$104,"*Kafr El Sheikh*") -> 2 | O10: =COUNTIFS(Clubs!$D$105:$D$121,"*Kafr El Sheikh*") -> 0 | P10: =COUNTIFS(Clubs!$D$122:$D$132,"*Kafr El Sheikh*") -> 0 | Q10: =SUMIF(Clubs!D:D,"*Kafr El Sheikh*",Clubs!F:F) -> 2 | R10: =(K10-AVERAGE(K$2:K$28))/_xlfn.STDEV.P(K$2:K$28) -> -0.44732678 | S10: =(L10-AVERAGE(L$2:L$28))/_xlfn.STDEV.P(L$2:L$28) -> -0.4198321 | T10: =(M10-AVERAGE(M$2:M$28))/_xlfn.STDEV.P(M$2:M$28) -> -0.57735027 | U10: =(N10-AVERAGE(N$2:N$28))/_xlfn.STDEV.P(N$2:N$28) -> -0.22327214 | V10: =(O10-AVERAGE(O$2:O$28))/_xlfn.STDEV.P(O$2:O$28) -> -0.29584238 | W10: =(P10-AVERAGE(P$2:P$28))/_xlfn.STDEV.P(P$2:P$28) -> -0.4110893 | X10: =SUM(R10*0.3)+(S10*0.3)+(T10*0.15)*(U10*0.07)*(V10*0.15)*(W10*0.03) -> -0.26014692 | Y10: =SUM(X10-J10) -> -0.020465738
A11: Menoufia | B11: 4891134 | C11: 2315 | D11: =SUM(B11/C11) -> 2112.8009 | E11: 34656 | F11: 7526 | G11: =(D11-AVERAGE(D$2:D$28))/_xlfn.STDEV.P(D$2:D$28) -> 0.91212533 | H11: =(E11-AVERAGE(E$2:E$28))/_xlfn.STDEV.P(E$2:E$28) -> -0.23618288 | I11: =(F11-AVERAGE(F$2:F$28))/_xlfn.STDEV.P(F$2:F$28) -> -0.56671596 | J11: =SUM((I11*0.3)+(H11*0.4)+(G11*0.3)) -> 0.0091496586 | K11: =COUNTIFS(Clubs!D:D,"*Menoufia*") -> 2 | L11: =COUNTIFS(Clubs!$D$2:$D$22,"*Menoufia*") -> 0 | M11: =COUNTIFS(Clubs!$D$23:$D$40,"*Menoufia*") -> 0 | N11: =COUNTIFS(Clubs!$D$41:$D$104,"*Menoufia*") -> 2 | O11: =COUNTIFS(Clubs!$D$105:$D$121,"*Menoufia*") -> 0 | P11: =COUNTIFS(Clubs!$D$122:$D$132,"*Manoufia*") -> 0 | Q11: =SUMIF(Clubs!D:D,"*Menoufia*",Clubs!F:F) -> 2 | R11: =(K11-AVERAGE(K$2:K$28))/_xlfn.STDEV.P(K$2:K$28) -> -0.44732678 | S11: =(L11-AVERAGE(L$2:L$28))/_xlfn.STDEV.P(L$2:L$28) -> -0.4198321 | T11: =(M11-AVERAGE(M$2:M$28))/_xlfn.STDEV.P(M$2:M$28) -> -0.57735027 | U11: =(N11-AVERAGE(N$2:N$28))/_xlfn.STDEV.P(N$2:N$28) -> -0.22327214 | V11: =(O11-AVERAGE(O$2:O$28))/_xlfn.STDEV.P(O$2:O$28) -> -0.29584238 | W11: =(P11-AVERAGE(P$2:P$28))/_xlfn.STDEV.P(P$2:P$28) -> -0.4110893 | X11: =SUM(R11*0.3)+(S11*0.3)+(T11*0.15)*(U11*0.07)*(V11*0.15)*(W11*0.03) -> -0.26014692 | Y11: =SUM(X11-J11) -> -0.26929658
A12: Qalyubia | B12: 6327362 | C12: 1335 | D12: =SUM(B12/C12) -> 4739.597 | E12: 74772 | F12: 12498 | G12: =(D12-AVERAGE(D$2:D$28))/_xlfn.STDEV.P(D$2:D$28) -> 3.0636905 | H12: =(E12-AVERAGE(E$2:E$28))/_xlfn.STDEV.P(E$2:E$28) -> 0.27037386 | I12: =(F12-AVERAGE(F$2:F$28))/_xlfn.STDEV.P(F$2:F$28) -> -0.35218753 | J12: =SUM((I12*0.3)+(H12*0.4)+(G12*0.3)) -> 0.92160043 | K12: =COUNTIFS(Clubs!D:D,"*Qalyubia*") -> 4 | L12: =COUNTIFS(Clubs!$D$2:$D$22,"*Qalyubia*") -> 0 | M12: =COUNTIFS(Clubs!$D$23:$D$40,"*Qalyubia*") -> 0 | N12: =COUNTIFS(Clubs!$D$41:$D$104,"*Qalyubia*") -> 4 | O12: =COUNTIFS(Clubs!$D$105:$D$121,"*Qalyubia*") -> 0 | P12: =COUNTIFS(Clubs!$D$122:$D$132,"*Qalyubia*") -> 0 | Q12: =SUMIF(Clubs!D:D,"*Qalyubia*",Clubs!F:F) -> 4 | R12: =(K12-AVERAGE(K$2:K$28))/_xlfn.STDEV.P(K$2:K$28) -> -0.13361709 | S12: =(L12-AVERAGE(L$2:L$28))/_xlfn.STDEV.P(L$2:L$28) -> -0.4198321 | T12: =(M12-AVERAGE(M$2:M$28))/_xlfn.STDEV.P(M$2:M$28) -> -0.57735027 | U12: =(N12-AVERAGE(N$2:N$28))/_xlfn.STDEV.P(N$2:N$28) -> 0.98239742 | V12: =(O12-AVERAGE(O$2:O$28))/_xlfn.STDEV.P(O$2:O$28) -> -0.29584238 | W12: =(P12-AVERAGE(P$2:P$28))/_xlfn.STDEV.P(P$2:P$28) -> -0.4110893 | X12: =SUM(R12*0.3)+(S12*0.3)+(T12*0.15)*(U12*0.07)*(V12*0.15)*(W12*0.03) -> -0.16603802 | Y12: =SUM(X12-J12) -> -1.0876385
A13: Sharkia | B13: 8181442 | C13: 4905 | D13: =SUM(B13/C13) -> 1667.98 | E13: 66563 | F13: 8663 | G13: =(D13-AVERAGE(D$2:D$28))/_xlfn.STDEV.P(D$2:D$28) -> 0.54777995 | H13: =(E13-AVERAGE(E$2:E$28))/_xlfn.STDEV.P(E$2:E$28) -> 0.16671636 | I13: =(F13-AVERAGE(F$2:F$28))/_xlfn.STDEV.P(F$2:F$28) -> -0.51765747 | J13: =SUM((I13*0.3)+(H13*0.4)+(G13*0.3)) -> 0.07572329 | K13: =COUNTIFS(Clubs!D:D,"*Sharkia*") -> 1 | L13: =COUNTIFS(Clubs!$D$2:$D$22,"*Sharkia*") -> 0 | M13: =COUNTIFS(Clubs!$D$23:$D$40,"*Sharkia*") -> 0 | N13: =COUNTIFS(Clubs!$D$41:$D$104,"*Sharkia*") -> 1 | O13: =COUNTIFS(Clubs!$D$105:$D$121,"*Sharkia*") -> 0 | P13: =COUNTIFS(Clubs!$D$122:$D$132,"*Sharkia*") -> 0 | Q13: =SUMIF(Clubs!D:D,"*Sharkia*",Clubs!F:F) -> 1 | R13: =(K13-AVERAGE(K$2:K$28))/_xlfn.STDEV.P(K$2:K$28) -> -0.60418163 | S13: =(L13-AVERAGE(L$2:L$28))/_xlfn.STDEV.P(L$2:L$28) -> -0.4198321 | T13: =(M13-AVERAGE(M$2:M$28))/_xlfn.STDEV.P(M$2:M$28) -> -0.57735027 | U13: =(N13-AVERAGE(N$2:N$28))/_xlfn.STDEV.P(N$2:N$28) -> -0.82610692 | V13: =(O13-AVERAGE(O$2:O$28))/_xlfn.STDEV.P(O$2:O$28) -> -0.29584238 | W13: =(P13-AVERAGE(P$2:P$28))/_xlfn.STDEV.P(P$2:P$28) -> -0.4110893 | X13: =SUM(R13*0.3)+(S13*0.3)+(T13*0.15)*(U13*0.07)*(V13*0.15)*(W13*0.03) -> -0.30720138 | Y13: =SUM(X13-J13) -> -0.38292467
A14: Assiut | B14: 5329830 | C14: 16367 | D14: =SUM(B14/C14) -> 325.6449 | E14: 27797 | F14: 5734 | G14: =(D14-AVERAGE(D$2:D$28))/_xlfn.STDEV.P(D$2:D$28) -> -0.55170449 | H14: =(E14-AVERAGE(E$2:E$28))/_xlfn.STDEV.P(E$2:E$28) -> -0.32279353 | I14: =(F14-AVERAGE(F$2:F$28))/_xlfn.STDEV.P(F$2:F$28) -> -0.64403594 | J14: =SUM((I14*0.3)+(H14*0.4)+(G14*0.3)) -> -0.48783954 | K14: =COUNTIFS(Clubs!D:D,"*Assiut*") -> 5 | L14: =COUNTIFS(Clubs!$D$2:$D$22,"*Assiut*") -> 0 | M14: =COUNTIFS(Clubs!$D$23:$D$40,"*Assiut*") -> 2 | N14: =COUNTIFS(Clubs!$D$41:$D$104,"*Assiut*") -> 2 | O14: =COUNTIFS(Clubs!$D$105:$D$121,"*Assiut*") -> 0 | P14: =COUNTIFS(Clubs!$D$122:$D$132,"*Assiut*") -> 1 | Q14: =SUMIF(Clubs!D:D,"*Assiut*",Clubs!F:F) -> 10 | R14: =(K14-AVERAGE(K$2:K$28))/_xlfn.STDEV.P(K$2:K$28) -> 0.023237755 | S14: =(L14-AVERAGE(L$2:L$28))/_xlfn.STDEV.P(L$2:L$28) -> -0.4198321 | T14: =(M14-AVERAGE(M$2:M$28))/_xlfn.STDEV.P(M$2:M$28) -> 1.1547005 | U14: =(N14-AVERAGE(N$2:N$28))/_xlfn.STDEV.P(N$2:N$28) -> -0.22327214 | V14: =(O14-AVERAGE(O$2:O$28))/_xlfn.STDEV.P(O$2:O$28) -> -0.29584238 | W14: =(P14-AVERAGE(P$2:P$28))/_xlfn.STDEV.P(P$2:P$28) -> 0.59794807 | X14: =SUM(R14*0.3)+(S14*0.3)+(T14*0.15)*(U14*0.07)*(V14*0.15)*(W14*0.03) -> -0.11897615 | Y14: =SUM(X14-J14) -> 0.36886339
A15: Aswan | B15: 1728544 | C15: 63307 | D15: =SUM(B15/C15) -> 27.304153 | E15: 16806 | F15: 10502 | G15: =(D15-AVERAGE(D$2:D$28))/_xlfn.STDEV.P(D$2:D$28) -> -0.79607045 | H15: =(E15-AVERAGE(E$2:E$28))/_xlfn.STDEV.P(E$2:E$28) -> -0.46158017 | I15: =(F15-AVERAGE(F$2:F$28))/_xlfn.STDEV.P(F$2:F$28) -> -0.43830956 | J15: =SUM((I15*0.3)+(H15*0.4)+(G15*0.3)) -> -0.55494607 | K15: =COUNTIFS(Clubs!D:D,"*Aswan*") -> 3 | L15: =COUNTIFS(Clubs!$D$2:$D$22,"*Aswan*") -> 0 | M15: =COUNTIFS(Clubs!$D$23:$D$40,"*Aswan*") -> 1 | N15: =COUNTIFS(Clubs!$D$41:$D$104,"*Aswan*") -> 2 | O15: =COUNTIFS(Clubs!$D$105:$D$121,"*Aswan*") -> 0 | P15: =COUNTIFS(Clubs!$D$122:$D$132,"*Aswan*") -> 0 | Q15: =SUMIF(Clubs!D:D,"*Aswan*",Clubs!F:F) -> 5 | R15: =(K15-AVERAGE(K$2:K$28))/_xlfn.STDEV.P(K$2:K$28) -> -0.29047194 | S15: =(L15-AVERAGE(L$2:L$28))/_xlfn.STDEV.P(L$2:L$28) -> -0.4198321 | T15: =(M15-AVERAGE(M$2:M$28))/_xlfn.STDEV.P(M$2:M$28) -> 0.28867513 | U15: =(N15-AVERAGE(N$2:N$28))/_xlfn.STDEV.P(N$2:N$28) -> -0.22327214 | V15: =(O15-AVERAGE(O$2:O$28))/_xlfn.STDEV.P(O$2:O$28) -> -0.29584238 | W15: =(P15-AVERAGE(P$2:P$28))/_xlfn.STDEV.P(P$2:P$28) -> -0.4110893 | X15: =SUM(R15*0.3)+(S15*0.3)+(T15*0.15)*(U15*0.07)*(V15*0.15)*(W15*0.03) -> -0.21309158 | Y15: =SUM(X15-J15) -> 0.34185449
A16: Beni Suef | B16: 3765659 | C16: 10209 | D16: =SUM(B16/C16) -> 368.85679 | E16: 19214 | F16: 5560 | G16: =(D16-AVERAGE(D$2:D$28))/_xlfn.STDEV.P(D$2:D$28) -> -0.51631035 | H16: =(E16-AVERAGE(E$2:E$28))/_xlfn.STDEV.P(E$2:E$28) -> -0.43117364 | I16: =(F16-AVERAGE(F$2:F$28))/_xlfn.STDEV.P(F$2:F$28) -> -0.65154357 | J16: =SUM((I16*0.3)+(H16*0.4)+(G16*0.3)) -> -0.52282563 | K16: =COUNTIFS(Clubs!D:D,"*Beni Suef*") -> 4 | L16: =COUNTIFS(Clubs!$D$2:$D$22,"*Beni Suef*") -> 0 | M16: =COUNTIFS(Clubs!$D$23:$D$40,"*Beni Suef*") -> 1 | N16: =COUNTIFS(Clubs!$D$41:$D$104,"*Beni Suef*") -> 3 | O16: =COUNTIFS(Clubs!$D$105:$D$121,"*Beni Suef*") -> 0 | P16: =COUNTIFS(Clubs!$D$122:$D$132,"*Beni Suef*") -> 0 | Q16: =SUMIF(Clubs!D:D,"*Beni Suef*",Clubs!F:F) -> 6 | R16: =(K16-AVERAGE(K$2:K$28))/_xlfn.STDEV.P(K$2:K$28) -> -0.13361709 | S16: =(L16-AVERAGE(L$2:L$28))/_xlfn.STDEV.P(L$2:L$28) -> -0.4198321 | T16: =(M16-AVERAGE(M$2:M$28))/_xlfn.STDEV.P(M$2:M$28) -> 0.28867513 | U16: =(N16-AVERAGE(N$2:N$28))/_xlfn.STDEV.P(N$2:N$28) -> 0.37956264 | V16: =(O16-AVERAGE(O$2:O$28))/_xlfn.STDEV.P(O$2:O$28) -> -0.29584238 | W16: =(P16-AVERAGE(P$2:P$28))/_xlfn.STDEV.P(P$2:P$28) -> -0.4110893 | X16: =SUM(R16*0.3)+(S16*0.3)+(T16*0.15)*(U16*0.07)*(V16*0.15)*(W16*0.03) -> -0.16603413 | Y16: =SUM(X16-J16) -> 0.3567915
A17: Fayoum | B17: 4273665 | C17: 5249 | D17: =SUM(B17/C17) -> 814.18651 | E17: 29419 | F17: 7490 | G17: =(D17-AVERAGE(D$2:D$28))/_xlfn.STDEV.P(D$2:D$28) -> -0.15154816 | H17: =(E17-AVERAGE(E$2:E$28))/_xlfn.STDEV.P(E$2:E$28) -> -0.30231205 | I17: =(F17-AVERAGE(F$2:F$28))/_xlfn.STDEV.P(F$2:F$28) -> -0.56826926 | J17: =SUM((I17*0.3)+(H17*0.4)+(G17*0.3)) -> -0.33687004 | K17: =COUNTIFS(Clubs!D:D,"*Fayoum*") -> 3 | L17: =COUNTIFS(Clubs!$D$2:$D$22,"*Fayoum*") -> 0 | M17: =COUNTIFS(Clubs!$D$23:$D$40,"*Fayoum*") -> 0 | N17: =COUNTIFS(Clubs!$D$41:$D$104,"*Fayoum*") -> 3 | O17: =COUNTIFS(Clubs!$D$105:$D$121,"*Fayoum*") -> 0 | P17: =COUNTIFS(Clubs!$D$122:$D$132,"*Fayoum*") -> 0 | Q17: =SUMIF(Clubs!D:D,"*Fayoum*",Clubs!F:F) -> 3 | R17: =(K17-AVERAGE(K$2:K$28))/_xlfn.STDEV.P(K$2:K$28) -> -0.29047194 | S17: =(L17-AVERAGE(L$2:L$28))/_xlfn.STDEV.P(L$2:L$28) -> -0.4198321 | T17: =(M17-AVERAGE(M$2:M$28))/_xlfn.STDEV.P(M$2:M$28) -> -0.57735027 | U17: =(N17-AVERAGE(N$2:N$28))/_xlfn.STDEV.P(N$2:N$28) -> 0.37956264 | V17: =(O17-AVERAGE(O$2:O$28))/_xlfn.STDEV.P(O$2:O$28) -> -0.29584238 | W17: =(P17-AVERAGE(P$2:P$28))/_xlfn.STDEV.P(P$2:P$28) -> -0.4110893 | X17: =SUM(R17*0.3)+(S17*0.3)+(T17*0.15)*(U17*0.07)*(V17*0.15)*(W17*0.03) -> -0.21309247 | Y17: =SUM(X17-J17) -> 0.12377757
A18: Giza | B18: 9832026 | C18: 37681 | D18: =SUM(B18/C18) -> 260.92795 | E18: 169694 | F18: 18347 | G18: =(D18-AVERAGE(D$2:D$28))/_xlfn.STDEV.P(D$2:D$28) -> -0.60471307 | H18: =(E18-AVERAGE(E$2:E$28))/_xlfn.STDEV.P(E$2:E$28) -> 1.4689824 | I18: =(F18-AVERAGE(F$2:F$28))/_xlfn.STDEV.P(F$2:F$28) -> -0.099818907 | J18: =SUM((I18*0.3)+(H18*0.4)+(G18*0.3)) -> 0.37623336 | K18: =COUNTIFS(Clubs!D:D,"*Giza*") -> 16 | L18: =COUNTIFS(Clubs!$D$2:$D$22,"*Giza*") -> 2 | M18: =COUNTIFS(Clubs!$D$23:$D$40,"*Giza*") -> 1 | N18: =COUNTIFS(Clubs!$D$41:$D$104,"*Giza*") -> 6 | O18: =COUNTIFS(Clubs!$D$105:$D$121,"*Giza*") -> 3 | P18: =COUNTIFS(Clubs!$D$122:$D$132,"*Giz*") -> 4 | Q18: =SUMIF(Clubs!D:D,"*Giza*",Clubs!F:F) -> 36 | R18: =(K18-AVERAGE(K$2:K$28))/_xlfn.STDEV.P(K$2:K$28) -> 1.7486411 | S18: =(L18-AVERAGE(L$2:L$28))/_xlfn.STDEV.P(L$2:L$28) -> 0.65973616 | T18: =(M18-AVERAGE(M$2:M$28))/_xlfn.STDEV.P(M$2:M$28) -> 0.28867513 | U18: =(N18-AVERAGE(N$2:N$28))/_xlfn.STDEV.P(N$2:N$28) -> 2.188067 | V18: =(O18-AVERAGE(O$2:O$28))/_xlfn.STDEV.P(O$2:O$28) -> 1.1137595 | W18: =(P18-AVERAGE(P$2:P$28))/_xlfn.STDEV.P(P$2:P$28) -> 3.6250602 | X18: =SUM(R18*0.3)+(S18*0.3)+(T18*0.15)*(U18*0.07)*(V18*0.15)*(W18*0.03) -> 0.72263366 | Y18: =SUM(X18-J18) -> 0.3464003
A19: Luxor | B19: 1466541 | C19: 5428 | D19: =SUM(B19/C19) -> 270.18073 | E19: 10276 | F19: 7596 | G19: =(D19-AVERAGE(D$2:D$28))/_xlfn.STDEV.P(D$2:D$28) -> -0.59713427 | H19: =(E19-AVERAGE(E$2:E$28))/_xlfn.STDEV.P(E$2:E$28) -> -0.54403644 | I19: =(F19-AVERAGE(F$2:F$28))/_xlfn.STDEV.P(F$2:F$28) -> -0.56369565 | J19: =SUM((I19*0.3)+(H19*0.4)+(G19*0.3)) -> -0.56586355 | K19: =COUNTIFS(Clubs!D:D,"*Luxor*") -> 2 | L19: =COUNTIFS(Clubs!$D$2:$D$22,"*Luxor*") -> 0 | M19: =COUNTIFS(Clubs!$D$23:$D$40,"*Luxor*") -> 0 | N19: =COUNTIFS(Clubs!$D$41:$D$104,"*Luxor*") -> 2 | O19: =COUNTIFS(Clubs!$D$105:$D$121,"*Luxor*") -> 0 | P19: =COUNTIFS(Clubs!$D$122:$D$132,"*Luxor*") -> 0 | Q19: =SUMIF(Clubs!D:D,"*Luxor*",Clubs!F:F) -> 2 | R19: =(K19-AVERAGE(K$2:K$28))/_xlfn.STDEV.P(K$2:K$28) -> -0.44732678 | S19: =(L19-AVERAGE(L$2:L$28))/_xlfn.STDEV.P(L$2:L$28) -> -0.4198321 | T19: =(M19-AVERAGE(M$2:M$28))/_xlfn.STDEV.P(M$2:M$28) -> -0.57735027 | U19: =(N19-AVERAGE(N$2:N$28))/_xlfn.STDEV.P(N$2:N$28) -> -0.22327214 | V19: =(O19-AVERAGE(O$2:O$28))/_xlfn.STDEV.P(O$2:O$28) -> -0.29584238 | W19: =(P19-AVERAGE(P$2:P$28))/_xlfn.STDEV.P(P$2:P$28) -> -0.4110893 | X19: =SUM(R19*0.3)+(S19*0.3)+(T19*0.15)*(U19*0.07)*(V19*0.15)*(W19*0.03) -> -0.26014692 | Y19: =SUM(X19-J19) -> 0.30571663
A20: Minya | B20: 6648928 | C20: 27057 | D20: =SUM(B20/C20) -> 245.73781 | E20: 28862 | F20: 4749 | G20: =(D20-AVERAGE(D$2:D$28))/_xlfn.STDEV.P(D$2:D$28) -> -0.61715506 | H20: =(E20-AVERAGE(E$2:E$28))/_xlfn.STDEV.P(E$2:E$28) -> -0.30934545 | I20: =(F20-AVERAGE(F$2:F$28))/_xlfn.STDEV.P(F$2:F$28) -> -0.68653604 | J20: =SUM((I20*0.3)+(H20*0.4)+(G20*0.3)) -> -0.51484551 | K20: =COUNTIFS(Clubs!D:D,"*Minya*") -> 4 | L20: =COUNTIFS(Clubs!$D$2:$D$22,"*Minya*") -> 0 | M20: =COUNTIFS(Clubs!$D$23:$D$40,"*Minya*") -> 0 | N20: =COUNTIFS(Clubs!$D$41:$D$104,"*Minya*") -> 2 | O20: =COUNTIFS(Clubs!$D$105:$D$121,"*Minya*") -> 0 | P20: =COUNTIFS(Clubs!$D$122:$D$132,"*Miny*") -> 2 | Q20: =SUMIF(Clubs!D:D,"*Minya*",Clubs!F:F) -> 6 | R20: =(K20-AVERAGE(K$2:K$28))/_xlfn.STDEV.P(K$2:K$28) -> -0.13361709 | S20: =(L20-AVERAGE(L$2:L$28))/_xlfn.STDEV.P(L$2:L$28) -> -0.4198321 | T20: =(M20-AVERAGE(M$2:M$28))/_xlfn.STDEV.P(M$2:M$28) -> -0.57735027 | U20: =(N20-AVERAGE(N$2:N$28))/_xlfn.STDEV.P(N$2:N$28) -> -0.22327214 | V20: =(O20-AVERAGE(O$2:O$28))/_xlfn.STDEV.P(O$2:O$28) -> -0.29584238 | W20: =(P20-AVERAGE(P$2:P$28))/_xlfn.STDEV.P(P$2:P$28) -> 1.6069854 | X20: =SUM(R20*0.3)+(S20*0.3)+(T20*0.15)*(U20*0.07)*(V20*0.15)*(W20*0.03) -> -0.16603765 | Y20: =SUM(X20-J20) -> 0.34880786
A21: Qena | B21: 3816168 | C21: 11033 | D21: =SUM(B21/C21) -> 345.8867 | E21: 17716 | F21: 5072 | G21: =(D21-AVERAGE(D$2:D$28))/_xlfn.STDEV.P(D$2:D$28) -> -0.53512476 | H21: =(E21-AVERAGE(E$2:E$28))/_xlfn.STDEV.P(E$2:E$28) -> -0.45008933 | I21: =(F21-AVERAGE(F$2:F$28))/_xlfn.STDEV.P(F$2:F$28) -> -0.67259946 | J21: =SUM((I21*0.3)+(H21*0.4)+(G21*0.3)) -> -0.542353 | K21: =COUNTIFS(Clubs!D:D,"*Qena*") -> 4 | L21: =COUNTIFS(Clubs!$D$2:$D$22,"*Qena*") -> 0 | M21: =COUNTIFS(Clubs!$D$23:$D$40,"*Qena*") -> 0 | N21: =COUNTIFS(Clubs!$D$41:$D$104,"*Qena*") -> 4 | O21: =COUNTIFS(Clubs!$D$105:$D$121,"*Qena*") -> 0 | P21: =COUNTIFS(Clubs!$D$122:$D$132,"*Qena*") -> 0 | Q21: =SUMIF(Clubs!D:D,"*Qena*",Clubs!F:F) -> 4 | R21: =(K21-AVERAGE(K$2:K$28))/_xlfn.STDEV.P(K$2:K$28) -> -0.13361709 | S21: =(L21-AVERAGE(L$2:L$28))/_xlfn.STDEV.P(L$2:L$28) -> -0.4198321 | T21: =(M21-AVERAGE(M$2:M$28))/_xlfn.STDEV.P(M$2:M$28) -> -0.57735027 | U21: =(N21-AVERAGE(N$2:N$28))/_xlfn.STDEV.P(N$2:N$28) -> 0.98239742 | V21: =(O21-AVERAGE(O$2:O$28))/_xlfn.STDEV.P(O$2:O$28) -> -0.29584238 | W21: =(P21-AVERAGE(P$2:P$28))/_xlfn.STDEV.P(P$2:P$28) -> -0.4110893 | X21: =SUM(R21*0.3)+(S21*0.3)+(T21*0.15)*(U21*0.07)*(V21*0.15)*(W21*0.03) -> -0.16603802 | Y21: =SUM(X21-J21) -> 0.37631498
A22: Sohag | B22: 6037081 | C22: 10400 | D22: =SUM(B22/C22) -> 580.48856 | E22: 23745 | F22: 4328 | G22: =(D22-AVERAGE(D$2:D$28))/_xlfn.STDEV.P(D$2:D$28) -> -0.34296628 | H22: =(E22-AVERAGE(E$2:E$28))/_xlfn.STDEV.P(E$2:E$28) -> -0.37395934 | I22: =(F22-AVERAGE(F$2:F$28))/_xlfn.STDEV.P(F$2:F$28) -> -0.70470106 | J22: =SUM((I22*0.3)+(H22*0.4)+(G22*0.3)) -> -0.46388394 | K22: =COUNTIFS(Clubs!D:D,"*Sohag*") -> 2 | L22: =COUNTIFS(Clubs!$D$2:$D$22,"*Sohag*") -> 0 | M22: =COUNTIFS(Clubs!$D$23:$D$40,"*Sohag*") -> 0 | N22: =COUNTIFS(Clubs!$D$41:$D$104,"*Sohag*") -> 2 | O22: =COUNTIFS(Clubs!$D$105:$D$121,"*Sohag*") -> 0 | P22: =COUNTIFS(Clubs!$D$122:$D$132,"*Sohag*") -> 0 | Q22: =SUMIF(Clubs!D:D,"*Sohag*",Clubs!F:F) -> 2 | R22: =(K22-AVERAGE(K$2:K$28))/_xlfn.STDEV.P(K$2:K$28) -> -0.44732678 | S22: =(L22-AVERAGE(L$2:L$28))/_xlfn.STDEV.P(L$2:L$28) -> -0.4198321 | T22: =(M22-AVERAGE(M$2:M$28))/_xlfn.STDEV.P(M$2:M$28) -> -0.57735027 | U22: =(N22-AVERAGE(N$2:N$28))/_xlfn.STDEV.P(N$2:N$28) -> -0.22327214 | V22: =(O22-AVERAGE(O$2:O$28))/_xlfn.STDEV.P(O$2:O$28) -> -0.29584238 | W22: =(P22-AVERAGE(P$2:P$28))/_xlfn.STDEV.P(P$2:P$28) -> -0.4110893 | X22: =SUM(R22*0.3)+(S22*0.3)+(T22*0.15)*(U22*0.07)*(V22*0.15)*(W22*0.03) -> -0.26014692 | Y22: =SUM(X22-J22) -> 0.20373701
A23: Matrouh | B23: 599616 | C23: 160252 | D23: =SUM(B23/C23) -> 3.7417068 | E23: 25463 | F23: 49777 | G23: =(D23-AVERAGE(D$2:D$28))/_xlfn.STDEV.P(D$2:D$28) -> -0.81537006 | H23: =(E23-AVERAGE(E$2:E$28))/_xlfn.STDEV.P(E$2:E$28) -> -0.35226564 | I23: =(F23-AVERAGE(F$2:F$28))/_xlfn.STDEV.P(F$2:F$28) -> 1.2563011 | J23: =SUM((I23*0.3)+(H23*0.4)+(G23*0.3)) -> -0.0086269518 | K23: =COUNTIFS(Clubs!D:D,"*Matrouh*") -> 3 | L23: =COUNTIFS(Clubs!$D$2:$D$22,"*Matrouh*") -> 0 | M23: =COUNTIFS(Clubs!$D$23:$D$40,"*Matrouh*") -> 0 | N23: =COUNTIFS(Clubs!$D$41:$D$104,"*Matrouh*") -> 3 | O23: =COUNTIFS(Clubs!$D$105:$D$121,"*Matrouh*") -> 0 | P23: =COUNTIFS(Clubs!$D$122:$D$132,"*Matrouh*") -> 0 | Q23: =SUMIF(Clubs!D:D,"*Matrouh*",Clubs!F:F) -> 3 | R23: =(K23-AVERAGE(K$2:K$28))/_xlfn.STDEV.P(K$2:K$28) -> -0.29047194 | S23: =(L23-AVERAGE(L$2:L$28))/_xlfn.STDEV.P(L$2:L$28) -> -0.4198321 | T23: =(M23-AVERAGE(M$2:M$28))/_xlfn.STDEV.P(M$2:M$28) -> -0.57735027 | U23: =(N23-AVERAGE(N$2:N$28))/_xlfn.STDEV.P(N$2:N$28) -> 0.37956264 | V23: =(O23-AVERAGE(O$2:O$28))/_xlfn.STDEV.P(O$2:O$28) -> -0.29584238 | W23: =(P23-AVERAGE(P$2:P$28))/_xlfn.STDEV.P(P$2:P$28) -> -0.4110893 | X23: =SUM(R23*0.3)+(S23*0.3)+(T23*0.15)*(U23*0.07)*(V23*0.15)*(W23*0.03) -> -0.21309247 | Y23: =SUM(X23-J23) -> -0.20446552
A24: New Valley | B24: 276546 | C24: 429151 | D24: =SUM(B24/C24) -> 0.64440255 | E24: 3738 | F24: 14423 | G24: =(D24-AVERAGE(D$2:D$28))/_xlfn.STDEV.P(D$2:D$28) -> -0.81790701 | H24: =(E24-AVERAGE(E$2:E$28))/_xlfn.STDEV.P(E$2:E$28) -> -0.62659372 | I24: =(F24-AVERAGE(F$2:F$28))/_xlfn.STDEV.P(F$2:F$28) -> -0.26912896 | J24: =SUM((I24*0.3)+(H24*0.4)+(G24*0.3)) -> -0.57674828 | K24: =COUNTIFS(Clubs!D:D,"*New Valley*") -> 0 | L24: =COUNTIFS(Clubs!$D$2:$D$22,"*New Valley*") -> 0 | M24: =COUNTIFS(Clubs!$D$23:$D$40,"*New Valley*") -> 0 | N24: =COUNTIFS(Clubs!$D$41:$D$104,"*New Valley*") -> 0 | O24: =COUNTIFS(Clubs!$D$105:$D$121,"*New Valley*") -> 0 | P24: =COUNTIFS(Clubs!$D$122:$D$132,"*New Valley*") -> 0 | Q24: =SUMIF(Clubs!D:D,"*New Valley*",Clubs!F:F) -> 0 | R24: =(K24-AVERAGE(K$2:K$28))/_xlfn.STDEV.P(K$2:K$28) -> -0.76103647 | S24: =(L24-AVERAGE(L$2:L$28))/_xlfn.STDEV.P(L$2:L$28) -> -0.4198321 | T24: =(M24-AVERAGE(M$2:M$28))/_xlfn.STDEV.P(M$2:M$28) -> -0.57735027 | U24: =(N24-AVERAGE(N$2:N$28))/_xlfn.STDEV.P(N$2:N$28) -> -1.4289417 | V24: =(O24-AVERAGE(O$2:O$28))/_xlfn.STDEV.P(O$2:O$28) -> -0.29584238 | W24: =(P24-AVERAGE(P$2:P$28))/_xlfn.STDEV.P(P$2:P$28) -> -0.4110893 | X24: =SUM(R24*0.3)+(S24*0.3)+(T24*0.15)*(U24*0.07)*(V24*0.15)*(W24*0.03) -> -0.35425583 | Y24: =SUM(X24-J24) -> 0.22249245
A25: North Sinai | B25: 477904 | C25: 26120 | D25: =SUM(B25/C25) -> 18.296478 | E25: 10783 | F25: 21891 | G25: =(D25-AVERAGE(D$2:D$28))/_xlfn.STDEV.P(D$2:D$28) -> -0.80344849 | H25: =(E25-AVERAGE(E$2:E$28))/_xlfn.STDEV.P(E$2:E$28) -> -0.5376344 | I25: =(F25-AVERAGE(F$2:F$28))/_xlfn.STDEV.P(F$2:F$28) -> 0.053095163 | J25: =SUM((I25*0.3)+(H25*0.4)+(G25*0.3)) -> -0.44015976 | K25: =COUNTIFS(Clubs!D:D,"*North Sinai*") -> 1 | L25: =COUNTIFS(Clubs!$D$2:$D$22,"*North Sinai*") -> 0 | M25: =COUNTIFS(Clubs!$D$23:$D$40,"*North Sinai*") -> 0 | N25: =COUNTIFS(Clubs!$D$41:$D$104,"*North Sinai*") -> 1 | O25: =COUNTIFS(Clubs!$D$105:$D$121,"*North Sinai*") -> 0 | P25: =COUNTIFS(Clubs!$D$122:$D$132,"*North Sinai*") -> 0 | Q25: =SUMIF(Clubs!D:D,"*North Sinai*",Clubs!F:F) -> 1 | R25: =(K25-AVERAGE(K$2:K$28))/_xlfn.STDEV.P(K$2:K$28) -> -0.60418163 | S25: =(L25-AVERAGE(L$2:L$28))/_xlfn.STDEV.P(L$2:L$28) -> -0.4198321 | T25: =(M25-AVERAGE(M$2:M$28))/_xlfn.STDEV.P(M$2:M$28) -> -0.57735027 | U25: =(N25-AVERAGE(N$2:N$28))/_xlfn.STDEV.P(N$2:N$28) -> -0.82610692 | V25: =(O25-AVERAGE(O$2:O$28))/_xlfn.STDEV.P(O$2:O$28) -> -0.29584238 | W25: =(P25-AVERAGE(P$2:P$28))/_xlfn.STDEV.P(P$2:P$28) -> -0.4110893 | X25: =SUM(R25*0.3)+(S25*0.3)+(T25*0.15)*(U25*0.07)*(V25*0.15)*(W25*0.03) -> -0.30720138 | Y25: =SUM(X25-J25) -> 0.13295838
A26: South Sinai | B26: 120043 | C26: 30948 | D26: =SUM(B26/C26) -> 3.8788613 | E26: 12866 | F26: 114190 | G26: =(D26-AVERAGE(D$2:D$28))/_xlfn.STDEV.P(D$2:D$28) -> -0.81525772 | H26: =(E26-AVERAGE(E$2:E$28))/_xlfn.STDEV.P(E$2:E$28) -> -0.51133173 | I26: =(F26-AVERAGE(F$2:F$28))/_xlfn.STDEV.P(F$2:F$28) -> 4.0355488 | J26: =SUM((I26*0.3)+(H26*0.4)+(G26*0.3)) -> 0.76155464 | K26: =COUNTIFS(Clubs!D:D,"*South Sinai*") -> 1 | L26: =COUNTIFS(Clubs!$D$2:$D$22,"*South Sinai*") -> 0 | M26: =COUNTIFS(Clubs!$D$23:$D$40,"*South Sinai*") -> 0 | N26: =COUNTIFS(Clubs!$D$41:$D$104,"*South Sinai*") -> 1 | O26: =COUNTIFS(Clubs!$D$105:$D$121,"*South Sinai*") -> 0 | P26: =COUNTIFS(Clubs!$D$122:$D$132,"*South Sinai*") -> 0 | Q26: =SUMIF(Clubs!D:D,"*South Sinai*",Clubs!F:F) -> 1 | R26: =(K26-AVERAGE(K$2:K$28))/_xlfn.STDEV.P(K$2:K$28) -> -0.60418163 | S26: =(L26-AVERAGE(L$2:L$28))/_xlfn.STDEV.P(L$2:L$28) -> -0.4198321 | T26: =(M26-AVERAGE(M$2:M$28))/_xlfn.STDEV.P(M$2:M$28) -> -0.57735027 | U26: =(N26-AVERAGE(N$2:N$28))/_xlfn.STDEV.P(N$2:N$28) -> -0.82610692 | V26: =(O26-AVERAGE(O$2:O$28))/_xlfn.STDEV.P(O$2:O$28) -> -0.29584238 | W26: =(P26-AVERAGE(P$2:P$28))/_xlfn.STDEV.P(P$2:P$28) -> -0.4110893 | X26: =SUM(R26*0.3)+(S26*0.3)+(T26*0.15)*(U26*0.07)*(V26*0.15)*(W26*0.03) -> -0.30720138 | Y26: =SUM(X26-J26) -> -1.068756
A27: Red Sea | B27: 419619 | C27: 120548 | D27: =SUM(B27/C27) -> 3.4809288 | E27: 16719 | F27: 42862 | G27: =(D27-AVERAGE(D$2:D$28))/_xlfn.STDEV.P(D$2:D$28) -> -0.81558366 | H27: =(E27-AVERAGE(E$2:E$28))/_xlfn.STDEV.P(E$2:E$28) -> -0.46267875 | I27: =(F27-AVERAGE(F$2:F$28))/_xlfn.STDEV.P(F$2:F$28) -> 0.95793742 | J27: =SUM((I27*0.3)+(H27*0.4)+(G27*0.3)) -> -0.14236537 | K27: =COUNTIFS(Clubs!D:D,"*Red Sea*") -> 2 | L27: =COUNTIFS(Clubs!$D$2:$D$22,"*Red Sea*") -> 1 | M27: =COUNTIFS(Clubs!$D$23:$D$40,"*Red Sea*") -> 0 | N27: =COUNTIFS(Clubs!$D$41:$D$104,"*Red Sea*") -> 0 | O27: =COUNTIFS(Clubs!$D$105:$D$121,"*Red Sea*") -> 1 | P27: =COUNTIFS(Clubs!$D$122:$D$132,"*Red Sea*") -> 0 | Q27: =SUMIF(Clubs!D:D,"*Red Sea*",Clubs!F:F) -> 8 | R27: =(K27-AVERAGE(K$2:K$28))/_xlfn.STDEV.P(K$2:K$28) -> -0.44732678 | S27: =(L27-AVERAGE(L$2:L$28))/_xlfn.STDEV.P(L$2:L$28) -> 0.11995203 | T27: =(M27-AVERAGE(M$2:M$28))/_xlfn.STDEV.P(M$2:M$28) -> -0.57735027 | U27: =(N27-AVERAGE(N$2:N$28))/_xlfn.STDEV.P(N$2:N$28) -> -1.4289417 | V27: =(O27-AVERAGE(O$2:O$28))/_xlfn.STDEV.P(O$2:O$28) -> 0.17402493 | W27: =(P27-AVERAGE(P$2:P$28))/_xlfn.STDEV.P(P$2:P$28) -> -0.4110893 | X27: =SUM(R27*0.3)+(S27*0.3)+(T27*0.15)*(U27*0.07)*(V27*0.15)*(W27*0.03) -> -0.098215214 | Y27: =SUM(X27-J27) -> 0.044150156
A28: Ismailia | B28: 1514708 | C28: 5375 | D28: =SUM(B28/C28) -> 281.80614 | E28: 20910 | F28: 14253 | G28: =(D28-AVERAGE(D$2:D$28))/_xlfn.STDEV.P(D$2:D$28) -> -0.58761209 | H28: =(E28-AVERAGE(E$2:E$28))/_xlfn.STDEV.P(E$2:E$28) -> -0.40975774 | I28: =(F28-AVERAGE(F$2:F$28))/_xlfn.STDEV.P(F$2:F$28) -> -0.276464 | J28: =SUM((I28*0.3)+(H28*0.4)+(G28*0.3)) -> -0.42312592 | K28: =COUNTIFS(Clubs!D:D,"*Ismailia*") -> 4 | L28: =COUNTIFS(Clubs!$D$2:$D$22,"*Ismailia*") -> 2 | M28: =COUNTIFS(Clubs!$D$23:$D$40,"*Ismailia*") -> 1 | N28: =COUNTIFS(Clubs!$D$41:$D$104,"*Ismailia*") -> 0 | O28: =COUNTIFS(Clubs!$D$105:$D$121,"*Ismail*") -> 0 | P28: =COUNTIFS(Clubs!$D$122:$D$132,"*Ismailia*") -> 1 | Q28: =SUMIF(Clubs!D2:D132,"*Ismailia*",Clubs!F2:F132) -> 15 | R28: =(K28-AVERAGE(K$2:K$28))/_xlfn.STDEV.P(K$2:K$28) -> -0.13361709 | S28: =(L28-AVERAGE(L$2:L$28))/_xlfn.STDEV.P(L$2:L$28) -> 0.65973616 | T28: =(M28-AVERAGE(M$2:M$28))/_xlfn.STDEV.P(M$2:M$28) -> 0.28867513 | U28: =(N28-AVERAGE(N$2:N$28))/_xlfn.STDEV.P(N$2:N$28) -> -1.4289417 | V28: =(O28-AVERAGE(O$2:O$28))/_xlfn.STDEV.P(O$2:O$28) -> -0.29584238 | W28: =(P28-AVERAGE(P$2:P$28))/_xlfn.STDEV.P(P$2:P$28) -> 0.59794807 | X28: =SUM(R28*0.3)+(S28*0.3)+(T28*0.15)*(U28*0.07)*(V28*0.15)*(W28*0.03) -> 0.15783917 | Y28: =SUM(X28-J28) -> 0.58096509
A29: Total | B29: =SUM(B2:B28) -> 108948531 | C29: =SUM(C2:C28) -> 1004470 | E29: =SUM(E2:E28) -> 1440724 | F29: =SUM(F2:F28) -> 557832 | K29: =SUM(K2:K28) -> 131 | L29: =SUM(L2:L28) -> 21 | M29: =SUM(M2:M28) -> 18 | N29: =SUM(N2:N28) -> 64 | O29: =SUM(O2:O28) -> 17 | P29: =SUM(P2:P28) -> 11 | Q29: =SUM(Q2:Q28) -> 296

Sheet Official By District
A1: Greater Cairo District Populations
A3: District | B3: Population | C3: Governorate | D3: Area km2 | E3: Density
A4: El Haram | B4: =SUM(398986+498899+718541) -> 1616426 | C4: Giza | D4: =SUM(23.9+48) -> 71.9 | E4: =SUM(B4/D4) -> 22481.586
A5: Shobra El Kheima | B5: =SUM(535436+754953) -> 1290389 | C5: Qalyoubeya | D5: 30 | E5: =SUM(B5/D5) -> 43012.967
A6: Bolaq El Dakrour | B6: 1046390 | C6: Giza | D6: 13 | E6: =SUM(B6/D6) -> 80491.538
A7: El Marg | B7: 865583 | C7: Cairo | D7: 41.96 | E7: =SUM(B7/D7) -> 20628.765
A8: El Waraq | B8: 807240 | C8: Giza | D8: 17 | E8: =SUM(B8/D8) -> 47484.706
A9: Madinet Nasr | B9: =SUM(687934+78209) -> 766143 | C9: Cairo | D9: 90 | E9: =SUM(B9/D9) -> 8512.7
A10: Imbaba | B10: 689430 | C10: Giza | D10: 8.28 | E10: =SUM(B10/D10) -> 83264.493
A11: El Salam | B11: =SUM(520983+166638) -> 687621 | C11: Cairo | D11: 12.67 | E11: =SUM(B11/D11) -> 54271.586
A12: Ain Shams | B12: 665926 | C12: Cairo | D12: 17 | E12: =SUM(B12/D12) -> 39172.118
A13: El Matareya | B13: 652955 | C13: Cairo | D13: 20 | E13: =SUM(B13/D13) -> 32647.75
A14: Toukh | B14: 639612 | C14: Qalyoubeya | D14: 1158 | E14: =SUM(B14/D14) -> 552.34197
A15: Markaz El Khanka | B15: 628006 | C15: Qalyoubeya | D15: 215.5 | E15: =SUM(B15/D15) -> 2914.181
A16: El Badrashin | B16: 615726 | C16: Giza | D16: 111 | E16: =SUM(B16/D16) -> 5547.0811
A17: Markaz Qalyoub | B17: 613459 | C17: Qalyoubeya | D17: 21.42 | E17: =SUM(B17/D17) -> 28639.542
A18: Manshyet El Qanater | B18: 595308 | C18: Giza | D18: 200 | E18: =SUM(B18/D18) -> 2976.54
A19: Shebin El Qanater | B19: 591321 | C19: Qalyoubeya | D19: 137 | E19: =SUM(B19/D19) -> 4316.2117
A20: Shobra Masr | B20: =SUM(83150+157888+342971) -> 584009 | C20: Cairo | D20: 2.8 | E20: =SUM(B20/D20) -> 208574.64
A21: Helwan | B21: 575008 | C21: Cairo | D21: 64.75 | E21: =SUM(B21/D21) -> 8880.4324
A22: Dar El Salam | B22: 569648 | C22: Cairo | D22: 75 | E22: =SUM(B22/D22) -> 7595.3067
A23: El Ayyat | B23: 566591 | C23: Giza | D23: 600 | E23: =SUM(B23/D23) -> 944.31833
A24: El Qanater | B24: 555446 | C24: Qalyoubeya | D24: 11.8 | E24: =SUM(B24/D24) -> 47071.695
A25: El Basatin | B25: 536864 | C25: Cairo | D25: 103 | E25: =SUM(B25/D25) -> 5212.2718
A26: Markaz Banha | B26: 527895 | C26: Qalyoubeya | D26: 1001 | E26: =SUM(B26/D26) -> 527.36763
A27: Kerdasa | B27: 509156 | C27: Giza | D27: 50 | E27: =SUM(B27/D27) -> 10183.12
A28: El Khosous | B28: 508653 | C28: Qalyoubeya | D28: 7.73 | E28: =SUM(B28/D28) -> 65802.458
A29: El Saff | B29: 480141 | C29: Giza | D29: 400 | E29: =SUM(B29/D29) -> 1200.3525
A30: 6th of Oct + Zayed | B30: =SUM(98865+101357+214007+64840) -> 479069 | C30: Giza | D30: 304.28 | E30: =SUM(B30/D30) -> 1574.4347
A31: Awsim | B31: 436926 | C31: Giza | D31: 30 | E31: =SUM(B31/D31) -> 14564.2
A32: Atfeeh | B32: 424450 | C32: Giza | D32: 2400 | E32: =SUM(B32/D32) -> 176.85417
A33: Abo El Nomros | B33: 419938 | C33: Giza | D33: 47.027 | E33: =SUM(B33/D33) -> 8929.7212
A34: El Zawya | B34: 344879 | C34: Cairo | D34: 8.86 | E34: =SUM(B34/D34) -> 38925.395
A35: El Hadayeq | B35: 342605 | C35: Cairo | D35: 6 | E35: =SUM(B35/D35) -> 57100.833
A36: Tagamoa | B36: =SUM(147206+98293+76811) -> 322310 | C36: Cairo | D36: 70.58 | E36: =SUM(B36/D36) -> 4566.5911
A37: El Giza | B37: 311426 | C37: Giza | D37: 98.84 | E37: =SUM(B37/D37) -> 3150.8094
A38: El Agouza | B38: 303545 | C38: Giza | D38: 8.59 | E38: =SUM(B38/D38) -> 35337.02
A39: Al Masara | B39: 292706 | C39: Cairo | D39: 27 | E39: =SUM(B39/D39) -> 10840.963
A40: Mansheyet Nasser | B40: 280018 | C40: Cairo | D40: 15.24 | E40: =SUM(B40/D40) -> 18373.885
A41: Masr El Qadima | B41: 271286 | C41: Cairo | D41: 19.24 | E41: =SUM(B41/D41) -> 14100.104
...

Sheet Players 1986-2026
A1: Player | B1: Birthdate | C1: City/Markaz | D1: Governorate | E1: Birth month
A2: Wael Gomaa | B2: 3/Aug/1975 | C2: Qotoor | D2: Gharbeya | E2: 44774
A3: Mohamed Homos | B3: 1/Jan/1979 | C3: Ismailia | D3: Ismailia | E3: 44562
A4: Abdelwahed El Sayed | B4: 3/June/1979 | C4: Tala | D4: Monofeya | E4: 44713
A5: Ahmed Hassan | B5: 2/May/1975 | C5: Maghagha | D5: Minya | E5: 44682
A6: El Sayed Hamdy | B6: 1/March/1984 | C6: Abo Gendir | D6: Fayoum | E6: 44621
A7: Mahmoud AbolSoud | B7: 30/Nov/1987 | C7: Mansoura | D7: Dakahleya | E7: 44866
A8: Ahmed AbdelGhani | B8: 1/Dec/1981 | C8: - | D8: Minya | E8: 44896
A9: Ahmed Shaaban | B9: 10/Oct/1978 | C9: Mansoura | D9: Dakahleya | E9: 44835
A10: Omar Gamal | B10: 16/Sept/1982 | C10: Samalout | D10: Minya | E10: 44805
A11: Shady Mohamed | B11: 29/Nov/1977 | C11: - | D11: Alexandria | E11: 44866
A12: Ahmed Raouf | B12: 15/Sept/1982 | C12: - | D12: Minya | E12: 44805
A13: Mohamed Shawky | B13: 5/Oct/1981 | C13: Port Said | D13: Port Said | E13: 44835
... A64: Ali Gabr | B64: 1/Jan/1989 | C64: Tanta | D64: Gharbeya | E64: 44562
A65: Sam Morsy | B65: N/A | C65: N/A | D65: N/A
A66: Ahmed Fathy | B66: 10/Nov/1984 | C66: Banha | D66: Qalyoubeya | E66: 44866
A67: Kahraba | B67: 13/April/1994 | C67: Masr El Adeema | D67: Cairo | E67: 44652
A68: Mohamed Abdelshafy | B68: 1/July/1985 | C68: El Marg | D68: Cairo | E68: 44743
A69: Shikabala | B69: 5/March/1996 | C69: Aswan | D69: Aswan | E69: 44621
A70: Saad Samir | B70: 1/April/1989 | C70: Banha | D70: Qalyoubeya | E70: 44652
A71: Ibrahim Salah | B71: 1/April/1987 | C71: Mansoura | D71: Dakahleya | E71: 44652
A72: Ahmed Dowidar | B72: 29/Oct/1987 | C72: Giza | D72: Giza | E72: 44835
A73: Karim Hafez | B73: 12/March/1996 | C73: - | D73: Beheira | E73: 44621
A74: Sherif Ekramy | B74: 10/July/1993 | C74: - | D74: Cairo | E74: 44743
A75: Mahmoud Fathalla | B75: 13/Feb/1982 | C75: Aga | D75: Dakahleya | E75: 44593
A76: Moatasem Salem | B76: 2/Sept/1980 | C76: - | D76: Cairo | E76: 44805
A77: Abdelzaher El Saqa | B77: 30/Jan/1974 | C77: Mansoura | D77: Dakahleya | E77: 44562
... A170: Yasser Ibrahim | B170: 10/Feb/1993 | C170: - | D170: Dakahleya | E170: 44593
A171: Ali Shehhata | B171: 25/April/1959 | D171: Cairo | E171: 45017
A172: Nasser El Telees | B172: - | C172: Aga | D172: Dakahleya | E172: 45170
A173: Islam Fathi | C173: Shebin El Kom | D173: Monofeya | E173: 44927
A174: Ayman Raggab | C174: Ain Shams | D174: Cairo | E174: 45108
A175: Talaat Mansour | C175: Helwan | D175: Cairo | E175: 44958
A176: Ahmed Said Oka | B176: 30754 | C176: Shobra | D176: Cairo | E176: 44986
A177: Ayman Shawki | D177: Alexandria | E177: 45261
A178: Saber Eid | D178: Gharbeya | E178: 45047
A179: Mohamed Hany | D179: Cairo | E179: 46054
A180: Marwan Attia | C180: Kafr El Dawwar | D180: Beheira | E180: 46235
A181: Mostafa Fathi | C181: Mansoura | D181: Dakahleya | E181: 46143
A182: Mahmoud Hamada | C182: Alexandria | D182: Alexandria | E182: 46174
...
